<?xml version="1.0"?>

<robot name="myfanuc">

    <link name="base_link">
        <visual>
            <geometry>
                <mesh filename="package://myfanuc_description/meshes/base_link.stl"/>
            </geometry>
            <origin xyz="0 0 0" rpy="0 0 0"/>
        </visual>
        <collision>
            <geometry>
                <mesh filename="package://myfanuc_description/meshes/base_link.stl"/>
            </geometry>
            <origin xyz="0 0 0" rpy="0 0 0"/>
        </collision>
    </link>

    <link name="link_1">
        <visual>
            <geometry>
                <mesh filename="package://myfanuc_description/meshes/link_1.stl"/>
            </geometry>
            <origin xyz="0 0 0" rpy="0 0 0"/>
        </visual>
        <collision>
            <geometry>
                <mesh filename="package://myfanuc_description/meshes/link_1.stl"/>
            </geometry>
            <origin xyz="0 0 0" rpy="0 0 0"/>
        </collision>
    </link>


    <link name="link_2">
        <visual>
            <geometry>
                <mesh filename="package://myfanuc_description/meshes/link_2.stl"/>
            </geometry>
            <origin xyz="0 0 0" rpy="0 0 0"/>
        </visual>
        <collision>
            <geometry>
                <mesh filename="package://myfanuc_description/meshes/link_2.stl"/>
            </geometry>
            <origin xyz="0 0 0" rpy="0 0 0"/>
        </collision>
    </link>


    <link name="link_3">
        <visual>
            <geometry>
                <mesh filename="package://myfanuc_description/meshes/link_3.stl"/>
            </geometry>
            <origin xyz="0 0 0" rpy="0 0 0"/>
        </visual>
        <collision>
            <geometry>
                <mesh filename="package://myfanuc_description/meshes/link_3.stl"/>
            </geometry>
            <origin xyz="0 0 0" rpy="0 0 0"/>
        </collision>
    </link>


    <link name="link_4">
        <visual>
            <geometry>
                <mesh filename="package://myfanuc_description/meshes/link_4.stl"/>
            </geometry>
            <origin xyz="0 0 0" rpy="0 0 0"/>
        </visual>
        <collision>
            <geometry>
                <mesh filename="package://myfanuc_description/meshes/link_4.stl"/>
            </geometry>
            <origin xyz="0 0 0" rpy="0 0 0"/>
        </collision>
    </link>


    <link name="link_5">
        <visual>
            <geometry>
                <mesh filename="package://myfanuc_description/meshes/link_5.stl"/>
            </geometry>
            <origin xyz="0 0 0" rpy="0 0 0"/>
        </visual>
        <collision>
            <geometry>
                <mesh filename="package://myfanuc_description/meshes/link_5.stl"/>
            </geometry>
            <origin xyz="0 0 0" rpy="0 0 0"/>
        </collision>
    </link>

    <link name="link_6">
        <visual>
            <geometry>
                <mesh filename="package://myfanuc_description/meshes/link_6.stl"/>
            </geometry>
            <origin xyz="0 0 0" rpy="0 0 0"/>
        </visual>
        <collision>
            <geometry>
                <mesh filename="package://myfanuc_description/meshes/link_6.stl"/>
            </geometry>
            <origin xyz="0 0 0" rpy="0 0 0"/>
        </collision>
    </link>

  <link name="tool0"/>
    
  <joint name="joint_1" type="revolute">
    <origin rpy="0 0 0" xyz="0 0 0.450"/>
    <parent link="base_link"/>
    <child link="link_1"/>
    <axis xyz="0 0 1"/>
    <limit effort="0" lower="-3.14" upper="3.14" velocity="3.67"/>
  </joint>
  <joint name="joint_2" type="revolute">
    <origin rpy="0 0 0" xyz="0.150 0 0"/>
    <parent link="link_1"/>
    <child link="link_2"/>
    <axis xyz="0 1 0"/>
    <limit effort="0" lower="-1.57" upper="2.79" velocity="3.32"/>
  </joint>
  <joint name="joint_3" type="revolute">
    <origin rpy="0 0 0" xyz="0 0 0.600"/>
    <parent link="link_2"/>
    <child link="link_3"/>
    <axis xyz="0 -1 0"/>
    <limit effort="0" lower="-3.14" upper="4.61" velocity="3.67"/>
  </joint>
  <joint name="joint_4" type="revolute">
    <origin rpy="0 0 0" xyz="0 0 0.200"/>
    <parent link="link_3"/>
    <child link="link_4"/>
    <axis xyz="-1 0 0"/>
    <limit effort="0" lower="-3.31" upper="3.31" velocity="6.98"/>
  </joint>
  <joint name="joint_5" type="revolute">
    <origin rpy="0 0 0" xyz="0.640 0 0"/>
    <parent link="link_4"/>
    <child link="link_5"/>
    <axis xyz="0 -1 0"/>
    <limit effort="0" lower="-3.31" upper="3.31" velocity="6.98"/>
  </joint>
  <joint name="joint_6" type="revolute">
    <origin rpy="0 0 0" xyz="0.100 0 0"/>
    <parent link="link_5"/>
    <child link="link_6"/>
    <axis xyz="-1 0 0"/>
    <limit effort="0" lower="-6.28" upper="6.28" velocity="10.47"/>
  </joint>
  <joint name="joint_6-tool0" type="fixed">
    <origin rpy="3.1415926535 -1.570796327 0" xyz="0 0 0"/>
    <parent link="link_6"/>
    <child link="tool0"/>
  </joint>
  <link name="base"/>
  <joint name="base_link-base" type="fixed">
    <origin rpy="0 0 0" xyz="0 0 0.450"/>
    <parent link="base_link"/>
    <child link="base"/>
  </joint>

</robot>